[2024-02-22T08:30:58.866+0000] {taskinstance.py:1159} INFO - Dependencies all met for dep_context=non-requeueable deps ti=<TaskInstance: test_s3_bucket.upload_to_s3 manual__2024-02-22T08:28:52.435860+00:00 [queued]>
[2024-02-22T08:30:58.872+0000] {taskinstance.py:1159} INFO - Dependencies all met for dep_context=requeueable deps ti=<TaskInstance: test_s3_bucket.upload_to_s3 manual__2024-02-22T08:28:52.435860+00:00 [queued]>
[2024-02-22T08:30:58.873+0000] {taskinstance.py:1361} INFO - Starting attempt 2 of 2
[2024-02-22T08:30:58.881+0000] {taskinstance.py:1382} INFO - Executing <Task(PythonOperator): upload_to_s3> on 2024-02-22 08:28:52.435860+00:00
[2024-02-22T08:30:58.884+0000] {standard_task_runner.py:57} INFO - Started process 1754 to run task
[2024-02-22T08:30:58.886+0000] {standard_task_runner.py:84} INFO - Running: ['***', 'tasks', 'run', 'test_s3_bucket', 'upload_to_s3', 'manual__2024-02-22T08:28:52.435860+00:00', '--job-id', '16', '--raw', '--subdir', 'DAGS_FOLDER/simples3bucketpipeline.py', '--cfg-path', '/tmp/tmp5wqav67m']
[2024-02-22T08:30:58.888+0000] {standard_task_runner.py:85} INFO - Job 16: Subtask upload_to_s3
[2024-02-22T08:30:58.918+0000] {task_command.py:416} INFO - Running <TaskInstance: test_s3_bucket.upload_to_s3 manual__2024-02-22T08:28:52.435860+00:00 [running]> on host f659216eeba3
[2024-02-22T08:30:58.969+0000] {taskinstance.py:1662} INFO - Exporting env vars: AIRFLOW_CTX_DAG_OWNER='Vishwaranjan' AIRFLOW_CTX_DAG_ID='test_s3_bucket' AIRFLOW_CTX_TASK_ID='upload_to_s3' AIRFLOW_CTX_EXECUTION_DATE='2024-02-22T08:28:52.435860+00:00' AIRFLOW_CTX_TRY_NUMBER='2' AIRFLOW_CTX_DAG_RUN_ID='manual__2024-02-22T08:28:52.435860+00:00'
[2024-02-22T08:30:58.976+0000] {base.py:73} INFO - Using connection ID 's3-conn' for task execution.
[2024-02-22T08:30:58.976+0000] {connection_wrapper.py:378} INFO - AWS Connection (conn_id='s3-conn', conn_type='aws') credentials retrieved from login and password.
[2024-02-22T08:31:02.413+0000] {taskinstance.py:1937} ERROR - Task failed with exception
Traceback (most recent call last):
  File "/home/airflow/.local/lib/python3.8/site-packages/airflow/operators/python.py", line 192, in execute
    return_value = self.execute_callable()
  File "/home/airflow/.local/lib/python3.8/site-packages/airflow/operators/python.py", line 209, in execute_callable
    return self.python_callable(*self.op_args, **self.op_kwargs)
  File "/opt/airflow/dags/simples3bucketpipeline.py", line 18, in upload_to_s3
    hook.load_file(filename=filename,key=key,bucket_name=bucket_name)
  File "/home/airflow/.local/lib/python3.8/site-packages/airflow/providers/amazon/aws/hooks/s3.py", line 135, in wrapper
    return func(*bound_args.args, **bound_args.kwargs)
  File "/home/airflow/.local/lib/python3.8/site-packages/airflow/providers/amazon/aws/hooks/s3.py", line 89, in wrapper
    return func(*bound_args.args, **bound_args.kwargs)
  File "/home/airflow/.local/lib/python3.8/site-packages/airflow/providers/amazon/aws/hooks/s3.py", line 1082, in load_file
    client.upload_file(filename, bucket_name, key, ExtraArgs=extra_args, Config=self.transfer_config)
  File "/home/airflow/.local/lib/python3.8/site-packages/boto3/s3/inject.py", line 143, in upload_file
    return transfer.upload_file(
  File "/home/airflow/.local/lib/python3.8/site-packages/boto3/s3/transfer.py", line 292, in upload_file
    future.result()
  File "/home/airflow/.local/lib/python3.8/site-packages/s3transfer/futures.py", line 103, in result
    return self._coordinator.result()
  File "/home/airflow/.local/lib/python3.8/site-packages/s3transfer/futures.py", line 266, in result
    raise self._exception
  File "/home/airflow/.local/lib/python3.8/site-packages/s3transfer/tasks.py", line 269, in _main
    self._submit(transfer_future=transfer_future, **kwargs)
  File "/home/airflow/.local/lib/python3.8/site-packages/s3transfer/upload.py", line 591, in _submit
    upload_input_manager.provide_transfer_size(transfer_future)
  File "/home/airflow/.local/lib/python3.8/site-packages/s3transfer/upload.py", line 244, in provide_transfer_size
    self._osutil.get_file_size(transfer_future.meta.call_args.fileobj)
  File "/home/airflow/.local/lib/python3.8/site-packages/s3transfer/utils.py", line 247, in get_file_size
    return os.path.getsize(filename)
  File "/usr/local/lib/python3.8/genericpath.py", line 50, in getsize
    return os.stat(filename).st_size
FileNotFoundError: [Errno 2] No such file or directory: 'Airflow/files/IPL_PLAYERS.csv'
[2024-02-22T08:31:02.434+0000] {taskinstance.py:1400} INFO - Marking task as FAILED. dag_id=test_s3_bucket, task_id=upload_to_s3, execution_date=20240222T082852, start_date=20240222T083058, end_date=20240222T083102
[2024-02-22T08:31:02.451+0000] {standard_task_runner.py:104} ERROR - Failed to execute job 16 for task upload_to_s3 ([Errno 2] No such file or directory: 'Airflow/files/IPL_PLAYERS.csv'; 1754)
[2024-02-22T08:31:02.464+0000] {local_task_job_runner.py:228} INFO - Task exited with return code 1
[2024-02-22T08:31:02.479+0000] {taskinstance.py:2778} INFO - 0 downstream tasks scheduled from follow-on schedule check
