[2024-02-22T08:38:05.383+0000] {taskinstance.py:1159} INFO - Dependencies all met for dep_context=non-requeueable deps ti=<TaskInstance: test_s3_bucket.upload_to_s3 manual__2024-02-22T08:38:03.419463+00:00 [queued]>
[2024-02-22T08:38:05.396+0000] {taskinstance.py:1159} INFO - Dependencies all met for dep_context=requeueable deps ti=<TaskInstance: test_s3_bucket.upload_to_s3 manual__2024-02-22T08:38:03.419463+00:00 [queued]>
[2024-02-22T08:38:05.397+0000] {taskinstance.py:1361} INFO - Starting attempt 1 of 2
[2024-02-22T08:38:05.407+0000] {taskinstance.py:1382} INFO - Executing <Task(PythonOperator): upload_to_s3> on 2024-02-22 08:38:03.419463+00:00
[2024-02-22T08:38:05.410+0000] {standard_task_runner.py:57} INFO - Started process 2276 to run task
[2024-02-22T08:38:05.413+0000] {standard_task_runner.py:84} INFO - Running: ['***', 'tasks', 'run', 'test_s3_bucket', 'upload_to_s3', 'manual__2024-02-22T08:38:03.419463+00:00', '--job-id', '19', '--raw', '--subdir', 'DAGS_FOLDER/simples3bucketpipeline.py', '--cfg-path', '/tmp/tmpd73v42fe']
[2024-02-22T08:38:05.416+0000] {standard_task_runner.py:85} INFO - Job 19: Subtask upload_to_s3
[2024-02-22T08:38:05.449+0000] {task_command.py:416} INFO - Running <TaskInstance: test_s3_bucket.upload_to_s3 manual__2024-02-22T08:38:03.419463+00:00 [running]> on host f659216eeba3
[2024-02-22T08:38:05.505+0000] {taskinstance.py:1662} INFO - Exporting env vars: AIRFLOW_CTX_DAG_OWNER='Vishwaranjan' AIRFLOW_CTX_DAG_ID='test_s3_bucket' AIRFLOW_CTX_TASK_ID='upload_to_s3' AIRFLOW_CTX_EXECUTION_DATE='2024-02-22T08:38:03.419463+00:00' AIRFLOW_CTX_TRY_NUMBER='1' AIRFLOW_CTX_DAG_RUN_ID='manual__2024-02-22T08:38:03.419463+00:00'
[2024-02-22T08:38:05.512+0000] {base.py:73} INFO - Using connection ID 's3-conn' for task execution.
[2024-02-22T08:38:05.513+0000] {connection_wrapper.py:378} INFO - AWS Connection (conn_id='s3-conn', conn_type='aws') credentials retrieved from login and password.
[2024-02-22T08:38:09.243+0000] {taskinstance.py:1937} ERROR - Task failed with exception
Traceback (most recent call last):
  File "/home/airflow/.local/lib/python3.8/site-packages/airflow/operators/python.py", line 192, in execute
    return_value = self.execute_callable()
  File "/home/airflow/.local/lib/python3.8/site-packages/airflow/operators/python.py", line 209, in execute_callable
    return self.python_callable(*self.op_args, **self.op_kwargs)
  File "/opt/airflow/dags/simples3bucketpipeline.py", line 18, in upload_to_s3
    hook.load_file(filename=filename,key=key,bucket_name=bucket_name)
  File "/home/airflow/.local/lib/python3.8/site-packages/airflow/providers/amazon/aws/hooks/s3.py", line 135, in wrapper
    return func(*bound_args.args, **bound_args.kwargs)
  File "/home/airflow/.local/lib/python3.8/site-packages/airflow/providers/amazon/aws/hooks/s3.py", line 89, in wrapper
    return func(*bound_args.args, **bound_args.kwargs)
  File "/home/airflow/.local/lib/python3.8/site-packages/airflow/providers/amazon/aws/hooks/s3.py", line 1067, in load_file
    raise ValueError(f"The key {key} already exists.")
ValueError: The key IPL_players.csv already exists.
[2024-02-22T08:38:09.260+0000] {taskinstance.py:1400} INFO - Marking task as UP_FOR_RETRY. dag_id=test_s3_bucket, task_id=upload_to_s3, execution_date=20240222T083803, start_date=20240222T083805, end_date=20240222T083809
[2024-02-22T08:38:09.277+0000] {standard_task_runner.py:104} ERROR - Failed to execute job 19 for task upload_to_s3 (The key IPL_players.csv already exists.; 2276)
[2024-02-22T08:38:09.319+0000] {local_task_job_runner.py:228} INFO - Task exited with return code 1
[2024-02-22T08:38:09.341+0000] {taskinstance.py:2778} INFO - 0 downstream tasks scheduled from follow-on schedule check
